Workbook

Sheet README
A1: WPP: Where Humans Stay in the Loop. Deliverable 8: Impact model
A3: Purpose | B3: Estimates how much elapsed time and hands-on cost the recommended three-lane, four-gate workflow (option B, Deliverables 6 and 7) could release for one campaign wave, against today's workflow (Deliverables 4 and 5), under three scenarios.
A4: Status | B4: Independent portfolio analysis using public information only. Not affiliated with or endorsed by WPP. WPP does not publish production volumes, hours or savings, so EVERY number except the cited facts is an ILLUSTRATIVE ASSUMPTION. Use the model to see what must be true, not as a forecast.
A5: How to use | B5: Change only the blue cells on the Inputs sheet. Every other sheet recalculates. Yellow cells are the assumptions that matter most.
A6: Colour code | B6: Blue text = input you can change. Black text = formula. Yellow fill = key assumption.
A7: Sheets | B7: Inputs: all assumptions. Model: hours, cost and days for today, the three scenarios and option A. Summary: headline results and charts. Sensitivity: one-at-a-time tests, the low-review-share test and payback by volume. Checks: tests that the model reconciles. Sources: where each cited fact comes from.
A8: Case | B8: One approved master campaign adapted for 20 markets, 6 channels and 4 versions each, which is 480 assets (one wave). Hours per asset and days come from Deliverables 4 and 5.
A9: Method | B9: Hours per asset = Lane 1 + Lane 2 + Lane 3 + rework + sample checks + rules set-up, each adjusted by scenario inputs. Cost per asset = hours x cost per hour + AI tool cost + platform cost per asset. Elapsed days = days outside review + days in review, approval and rework, taken stage by stage from Deliverable 7. Annual figures multiply the per-wave result by the number of waves in scope. No discounting.
A10: Important | B10: Hours released are capacity, not cash. They become savings only if the capacity is redeployed to other work or volume grows. WPP says WPP Production does not anticipate layoffs [11]. The unattributed claim of "up to 70%" faster production [6] is not used as a scenario input; it is shown for reference on the Summary sheet.
A11: Limits | B11: Single case, single rate card, no discounting, no client-side value from faster delivery, no change in volume from the new workflow, and one-off costs are placeholders.

Sheet Inputs
A1: Inputs and assumptions
A2: Blue = edit me. Yellow = key assumption. All figures are illustrative assumptions unless a source is shown.
A4: Case and rates | B4: Unit | D4: Value | F4: Basis
A5: Case size and rates
A6: Markets | B6: number | D6: 20 | F6: ASSUMPTION (Deliverable 4): a large global brand.
A7: Channels | B7: number | D7: 6 | F7: ASSUMPTION (Deliverable 4).
A8: Versions per market and channel | B8: number | D8: 4 | F8: ASSUMPTION (Deliverable 4).
A9: Assets per wave | B9: number | D9: =D6*D7*D8 -> 480 | F9: Formula: 20 x 6 x 4 = 480.
A10: Blended cost per hour | B10: £ | D10: 60 | F10: ASSUMPTION (Deliverable 4): illustrative rate card, no public source.
A11: Productive hours per full-time person per year | B11: hours | D11: 1600 | F11: ASSUMPTION: used only to convert hours into full-time equivalents.
A12: Waves of this size in scope per year at full rollout | B12: number | D12: 60 | F12: ASSUMPTION: for example 12 clients with 5 waves each. WPP publishes no volumes [11][12]. Tested from 10 to 100 on Sensitivity.
A13: Today (from Deliverables 4 and 5)
A14: Lane 1 hands-on hours per asset | B14: hours | D14: 0.92 | F14: Deliverable 5: tasks T2, T4, T7, T8, T12.
A15: Lane 2 hands-on hours per asset | B15: hours | D15: 1.38 | F15: Deliverable 5: tasks T1, T3, T5, T6, T11.
A16: Lane 3 hands-on hours per asset | B16: hours | D16: 0.3 | F16: Deliverable 5: tasks T9, T10, T13.
A17: Share of assets reworked today | B17: % | D17: =1/3 -> 0.33333333 | F17: ASSUMPTION (Deliverable 4): about 1 in 3.
A18: Hands-on hours per reworked asset | B18: hours | D18: 1.8 | F18: ASSUMPTION: chosen so that rework averages 0.6 hours per asset (Deliverable 5).
A19: Rework hours per asset today | B19: hours | D19: =D17*D18 -> 0.6 | F19: Formula.
A20: Hands-on hours per asset today | B20: hours | D20: =SUM(D14:D16)+D19 -> 3.2 | F20: Formula: 3.2 hours.
A21: Days today outside review, approval and rework | B21: days | D21: 13 | F21: Deliverable 4: 28 days less 15.
A22: Days today in review, approval and rework | B22: days | D22: 15 | F22: ASSUMPTION built to fit survey signals [9]; tested on Sensitivity (Deliverable 4 caution).
A23: Total days today | B23: days | D23: =D21+D22 -> 28 | F23: Formula: 28 days.
A25: Scenario inputs | B25: Unit | C25: Cautious | D25: Central | E25: Optimistic | F25: Basis
A26: Hands-on hours
A27: Lane 1 hours cut by AI working under agreed rules | B27: % | C27: 0.35 | D27: 0.5 | E27: 0.7 | F27: ASSUMPTION. Lane 1 tasks are repeatable and rule-bound (Deliverable 5). 70% matches the unattributed "up to 70%" claim [6] and is used only in the optimistic case.
A28: Lane 2 hours cut by AI drafting with people finishing | B28: % | C28: 0.1 | D28: 0.2 | E28: 0.45 | F28: ASSUMPTION. AI drafts, people edit; the saving is smaller than in Lane 1.
A29: Change in Lane 3 hours (positive = more) | B29: % | C29: 0.1 | D29: 0 | E29: -0.1 | F29: ASSUMPTION. Every Lane 3 item is still checked by a person; logs and tools may add or save a little time.
A30: Share of assets reworked in the new design | B30: % | C30: 0.25 | D30: 0.15 | E30: 0.1 | F30: ASSUMPTION. Earlier approval of rules and a first sample should cut changes late in the cycle [9].
A31: Share of assets sampled at the gates | B31: % | C31: 0.15 | D31: 0.1 | E31: 0.05 | F31: ASSUMPTION (Deliverable 7): about 1 in 10.
A32: Hours to check each sampled asset | B32: hours | C32: 0.3 | D32: 0.25 | E32: 0.2 | F32: ASSUMPTION.
A33: Hours to set up rules and pattern, per wave | B33: hours | C33: 60 | D33: 40 | E33: 24 | F33: ASSUMPTION. Writing brand and AI-use rules as checkable rules; higher in a first wave for a client.
A34: Other costs
A35: AI tool cost per asset | B35: £ | C35: 3 | D35: 1 | E35: 0.5 | F35: ASSUMPTION. Generation, translation and checking services.
A36: Platform and licences allocated per wave | B36: £ | C36: 3000 | D36: 2000 | E36: 1000 | F36: ASSUMPTION. WPP already runs WPP Open [10], so this is only the extra cost allocated to a wave.
A37: One-off programme cost | B37: £ | C37: 2000000 | D37: 1200000 | E37: 900000 | F37: ASSUMPTION. Pilot, rules library, integration and training. Placeholder.
A38: Elapsed days in the new design (Deliverable 7, working days)
A39: Set the rules and brief (Gate 1) | B39: days | C39: 4 | D39: 3 | E39: 3 | F39: Deliverable 7 central: 3.
A40: Prove the pattern, excluding the Gate 2 decision | B40: days | C40: 2 | D40: 2 | E40: 2 | F40: Deliverable 7 central: 2 of the 3 days.
A41: Produce in Lanes 1 and 2 | B41: days | C41: 5 | D41: 4 | E41: 2 | F41: Deliverable 7 central: 4.
A42: Deliver | B42: days | C42: 1 | D42: 1 | E42: 1 | F42: Deliverable 7 central: 1.
...

Sheet Model
A1: Model: hours, cost and days per wave
A2: All cells are formulas. Edit the Inputs sheet only. Columns: today, the three scenarios for option B, and option A (central).
A4: Per asset unless stated | B4: Today | C4: Cautious | D4: Central | E4: Optimistic | F4: Option A (bolt-on, central)
A5: Hands-on hours per asset
A6: Lane 1: repeatable work (AI under rules) | B6: =Inputs!D14 -> 0.92 | C6: =Inputs!$D$14*(1-Inputs!C27) -> 0.598 | D6: =Inputs!$D$14*(1-Inputs!D27) -> 0.46 | E6: =Inputs!$D$14*(1-Inputs!E27) -> 0.276 | F6: =Inputs!$D$14*(1-Inputs!D50) -> 0.644
A7: Lane 2: AI drafts, people finish | B7: =Inputs!D15 -> 1.38 | C7: =Inputs!$D$15*(1-Inputs!C28) -> 1.242 | D7: =Inputs!$D$15*(1-Inputs!D28) -> 1.104 | E7: =Inputs!$D$15*(1-Inputs!E28) -> 0.759 | F7: =Inputs!$D$15*(1-Inputs!D51) -> 1.242
A8: Lane 3: people decide | B8: =Inputs!D16 -> 0.3 | C8: =Inputs!$D$16*(1+Inputs!C29) -> 0.33 | D8: =Inputs!$D$16*(1+Inputs!D29) -> 0.3 | E8: =Inputs!$D$16*(1+Inputs!E29) -> 0.27 | F8: =Inputs!D16 -> 0.3
A9: Rework after review | B9: =Inputs!D19 -> 0.6 | C9: =Inputs!C30*Inputs!$D$18 -> 0.45 | D9: =Inputs!D30*Inputs!$D$18 -> 0.27 | E9: =Inputs!E30*Inputs!$D$18 -> 0.18 | F9: =Inputs!D19 -> 0.6
A10: Sample checks at gates | B10: 0 | C10: =Inputs!C31*Inputs!C32 -> 0.045 | D10: =Inputs!D31*Inputs!D32 -> 0.025 | E10: =Inputs!E31*Inputs!E32 -> 0.01 | F10: 0
A11: Rules and pattern set-up (per asset) | B11: 0 | C11: =Inputs!C33/Inputs!$D$9 -> 0.125 | D11: =Inputs!D33/Inputs!$D$9 -> 0.083333333 | E11: =Inputs!E33/Inputs!$D$9 -> 0.05 | F11: 0
A12: Total hands-on hours per asset | B12: =SUM(B6:B11) -> 3.2 | C12: =SUM(C6:C11) -> 2.79 | D12: =SUM(D6:D11) -> 2.2423333 | E12: =SUM(E6:E11) -> 1.545 | F12: =SUM(F6:F11) -> 2.786
A13: Change against today | B13: 0 | C13: =C12/$B$12-1 -> -0.128125 | D13: =D12/$B$12-1 -> -0.29927083 | E13: =E12/$B$12-1 -> -0.5171875 | F13: =F12/$B$12-1 -> -0.129375
A14: Cost per asset (£)
A15: Hands-on cost | B15: =B12*Inputs!$D$10 -> 192 | C15: =C12*Inputs!$D$10 -> 167.4 | D15: =D12*Inputs!$D$10 -> 134.54 | E15: =E12*Inputs!$D$10 -> 92.7 | F15: =F12*Inputs!$D$10 -> 167.16
A16: AI tool cost | B16: 0 | C16: =Inputs!C35 -> 3 | D16: =Inputs!D35 -> 1 | E16: =Inputs!E35 -> 0.5 | F16: =Inputs!D35 -> 1
A17: Platform and licences (per asset) | B17: 0 | C17: =Inputs!C36/Inputs!$D$9 -> 6.25 | D17: =Inputs!D36/Inputs!$D$9 -> 4.1666667 | E17: =Inputs!E36/Inputs!$D$9 -> 2.0833333 | F17: =Inputs!D36/Inputs!$D$9 -> 4.1666667
A18: Total cost per asset | B18: =SUM(B15:B17) -> 192 | C18: =SUM(C15:C17) -> 176.65 | D18: =SUM(D15:D17) -> 139.70667 | E18: =SUM(E15:E17) -> 95.283333 | F18: =SUM(F15:F17) -> 172.32667
A19: Change against today | B19: 0 | C19: =C18/$B$18-1 -> -0.079947917 | D19: =D18/$B$18-1 -> -0.27236111 | E19: =E18/$B$18-1 -> -0.50373264 | F19: =F18/$B$18-1 -> -0.10246528
A20: Cost of one wave (£) | B20: =B18*Inputs!$D$9 -> 92160 | C20: =C18*Inputs!$D$9 -> 84792 | D20: =D18*Inputs!$D$9 -> 67059.2 | E20: =E18*Inputs!$D$9 -> 45736 | F20: =F18*Inputs!$D$9 -> 82716.8
A21: Hours and cost released
A22: Hours saved per asset | C22: =$B$12-C12 -> 0.41 | D22: =$B$12-D12 -> 0.95766667 | E22: =$B$12-E12 -> 1.655 | F22: =$B$12-F12 -> 0.414
A23: Hours saved per wave | C23: =C22*Inputs!$D$9 -> 196.8 | D23: =D22*Inputs!$D$9 -> 459.68 | E23: =E22*Inputs!$D$9 -> 794.4 | F23: =F22*Inputs!$D$9 -> 198.72
A24: Net cost saved per wave (£) | C24: =($B$18-C18)*Inputs!$D$9 -> 7368 | D24: =($B$18-D18)*Inputs!$D$9 -> 25100.8 | E24: =($B$18-E18)*Inputs!$D$9 -> 46424 | F24: =($B$18-F18)*Inputs!$D$9 -> 9443.2
A25: Hours saved per year at full rollout | C25: =C23*Inputs!$D$12 -> 11808 | D25: =D23*Inputs!$D$12 -> 27580.8 | E25: =E23*Inputs!$D$12 -> 47664 | F25: =F23*Inputs!$D$12 -> 11923.2
A26: Capacity released (full-time equivalents) | C26: =C25/Inputs!$D$11 -> 7.38 | D26: =D25/Inputs!$D$11 -> 17.238 | E26: =E25/Inputs!$D$11 -> 29.79 | F26: =F25/Inputs!$D$11 -> 7.452
A27: Net cost saved per year (£) | C27: =C24*Inputs!$D$12 -> 442080 | D27: =D24*Inputs!$D$12 -> 1506048 | E27: =E24*Inputs!$D$12 -> 2785440 | F27: =F24*Inputs!$D$12 -> 566592
A28: One-off programme cost (£) | C28: =Inputs!C37 -> 2000000 | D28: =Inputs!D37 -> 1200000 | E28: =Inputs!E37 -> 900000 | F28: n/a
A29: Payback (months) | C29: =IF(C27<=0,"n/a",C28/(C27/12)) -> 54.288817 | D29: =IF(D27<=0,"n/a",D28/(D27/12)) -> 9.5614482 | E29: =IF(E27<=0,"n/a",E28/(E27/12)) -> 3.8773048 | F29: n/a
A30: Elapsed time (working days)
A31: Days outside review, approval and rework | B31: =Inputs!D21 -> 13 | C31: =Inputs!C39+Inputs!C40+Inputs!C41+Inputs!C42 -> 12 | D31: =Inputs!D39+Inputs!D40+Inputs!D41+Inputs!D42 -> 10 | E31: =Inputs!E39+Inputs!E40+Inputs!E41+Inputs!E42 -> 8 | F31: =Inputs!D52 -> 11
A32: Days in review, approval and rework | B32: =Inputs!D22 -> 15 | C32: =SUM(Inputs!C43:C47) -> 10 | D32: =SUM(Inputs!D43:D47) -> 8 | E32: =SUM(Inputs!E43:E47) -> 6 | F32: =Inputs!D53 -> 15
A33: Total days | B33: =B31+B32 -> 28 | C33: =C31+C32 -> 22 | D33: =D31+D32 -> 18 | E33: =E31+E32 -> 14 | F33: =F31+F32 -> 26
A34: Change against today | B34: 0 | C34: =C33/$B$33-1 -> -0.21428571 | D34: =D33/$B$33-1 -> -0.35714286 | E34: =E33/$B$33-1 -> -0.5 | F34: =F33/$B$33-1 -> -0.071428571
A35: Review share of days | B35: =B32/B33 -> 0.53571429 | C35: =C32/C33 -> 0.45454545 | D35: =D32/D33 -> 0.44444444 | E35: =E32/E33 -> 0.42857143 | F35: =F32/F33 -> 0.57692308
A36: Where the hours saved come from (per asset)
A37: Lane 1 automation | C37: =$B$6-C6 -> 0.322 | D37: =$B$6-D6 -> 0.46 | E37: =$B$6-E6 -> 0.644 | F37: =$B$6-F6 -> 0.276
A38: Lane 2 AI drafting | C38: =$B$7-C7 -> 0.138 | D38: =$B$7-D7 -> 0.276 | E38: =$B$7-E7 -> 0.621 | F38: =$B$7-F7 -> 0.138
A39: Lane 3 change | C39: =$B$8-C8 -> -0.03 | D39: =$B$8-D8 -> 0 | E39: =$B$8-E8 -> 0.03 | F39: =$B$8-F8 -> 0
A40: Fewer reworked assets | C40: =$B$9-C9 -> 0.15 | D40: =$B$9-D9 -> 0.33 | E40: =$B$9-E9 -> 0.42 | F40: =$B$9-F9 -> 0
A41: Added sample-check and set-up hours | C41: =-(C10+C11) -> -0.17 | D41: =-(D10+D11) -> -0.10833333 | E41: =-(E10+E11) -> -0.06 | F41: =-(F10+F11) -> 0
...

Sheet Summary
A1: Summary: what the redesign could release per campaign wave
A2: Illustrative results linked from the Model sheet. Not WPP data.
A4: Measure | B4: Today | C4: Cautious | D4: Central | E4: Optimistic | F4: Option A (central)
A5: Hands-on hours per asset | B5: =Model!B12 -> 3.2 | C5: =Model!C12 -> 2.79 | D5: =Model!D12 -> 2.2423333 | E5: =Model!E12 -> 1.545 | F5: =Model!F12 -> 2.786
A6: Total cost per asset (£) | B6: =Model!B18 -> 192 | C6: =Model!C18 -> 176.65 | D6: =Model!D18 -> 139.70667 | E6: =Model!E18 -> 95.283333 | F6: =Model!F18 -> 172.32667
A7: Cost per asset: change against today | B7: =Model!B19 -> 0 | C7: =Model!C19 -> -0.079947917 | D7: =Model!D19 -> -0.27236111 | E7: =Model!E19 -> -0.50373264 | F7: =Model!F19 -> -0.10246528
A8: Elapsed working days per wave | B8: =Model!B33 -> 28 | C8: =Model!C33 -> 22 | D8: =Model!D33 -> 18 | E8: =Model!E33 -> 14 | F8: =Model!F33 -> 26
A9: Elapsed days: change against today | B9: =Model!B34 -> 0 | C9: =Model!C34 -> -0.21428571 | D9: =Model!D34 -> -0.35714286 | E9: =Model!E34 -> -0.5 | F9: =Model!F34 -> -0.071428571
A10: Days in review, approval and rework | B10: =Model!B32 -> 15 | C10: =Model!C32 -> 10 | D10: =Model!D32 -> 8 | E10: =Model!E32 -> 6 | F10: =Model!F32 -> 15
A11: Capacity released per year (full-time equivalents) | B11: =Model!B26 -> 0 | C11: =Model!C26 -> 7.38 | D11: =Model!D26 -> 17.238 | E11: =Model!E26 -> 29.79 | F11: =Model!F26 -> 7.452
A12: Net cost saved per year (£) | B12: =Model!B27 -> 0 | C12: =Model!C27 -> 442080 | D12: =Model!D27 -> 1506048 | E12: =Model!E27 -> 2785440 | F12: =Model!F27 -> 566592
A13: Payback on one-off cost (months) | B13: =Model!B29 -> 0 | C13: =Model!C29 -> 54.288817 | D13: =Model!D29 -> 9.5614482 | E13: =Model!E29 -> 3.8773048 | F13: =Model!F29 -> n/a
A14: Share of net hours saved from Lane 1 and 2 work | B14: =Model!B43 -> 0 | C14: =Model!C43 -> 1.1219512 | D14: =Model!D43 -> 0.76853463 | E14: =Model!E43 -> 0.76435045 | F14: =Model!F43 -> 1
A15: Share of net hours saved from fewer reworked assets | B15: =Model!B44 -> 0 | C15: =Model!C44 -> 0.36585366 | D15: =Model!D44 -> 0.34458754 | E15: =Model!E44 -> 0.25377644 | F15: =Model!F44 -> 0
A16: Share of days saved from review, approval and rework | B16: =Model!B49 -> 0 | C16: =Model!C49 -> 0.83333333 | D16: =Model!D49 -> 0.7 | E16: =Model!E49 -> 0.64285714 | F16: =Model!F49 -> 0
A18: Reference only: the unattributed claim of up to 70% faster content production [6] would imply this many days | E18: =Model!B33*(1-0.7) -> 8.4
A19: Note: capacity released is not cash. WPP says it does not anticipate layoffs in WPP Production [11].

Sheet Sensitivity
A1: Sensitivity: what moves the answer
A2: All cells are formulas on the central scenario. Each test changes one input at a time.
A4: A. Cost per asset saving (against today) when one input moves from its cautious to its optimistic value, other inputs central
A5: Input | B5: Cautious value | C5: Central value | D5: Optimistic value | E5: Saving at cautious value | F5: Saving at optimistic value | G5: Swing (points)
A6: Lane 1 hours cut | B6: =Inputs!C27 -> 0.35 | C6: =Inputs!D27 -> 0.5 | D6: =Inputs!E27 -> 0.7 | E6: =1-((Inputs!$D$14*(1-Inputs!$C$27)+Inputs!$D$15*(1-Inputs!$D$28)+Inputs!$D$16*(1+Inputs!$D$29)+Inputs!$D$30*Inputs!$D$18+Inputs!$D$31*Inputs!$D$32+Inputs!$D$33/Inputs!$D$9)*Inputs!$D$10+Inputs!$D$35+Inputs!$D$36/Inputs!$D$9)/Model!$B$18 -> 0.22923611 | F6: =1-((Inputs!$D$14*(1-Inputs!$E$27)+Inputs!$D$15*(1-Inputs!$D$28)+Inputs!$D$16*(1+Inputs!$D$29)+Inputs!$D$30*Inputs!$D$18+Inputs!$D$31*Inputs!$D$32+Inputs!$D$33/Inputs!$D$9)*Inputs!$D$10+Inputs!$D$35+Inputs!$D$36/Inputs!$D$9)/Model!$B$18 -> 0.32986111 | G6: =(F6-E6)*100 -> 10.0625
A7: Lane 2 hours cut | B7: =Inputs!C28 -> 0.1 | C7: =Inputs!D28 -> 0.2 | D7: =Inputs!E28 -> 0.45 | E7: =1-((Inputs!$D$14*(1-Inputs!$D$27)+Inputs!$D$15*(1-Inputs!$C$28)+Inputs!$D$16*(1+Inputs!$D$29)+Inputs!$D$30*Inputs!$D$18+Inputs!$D$31*Inputs!$D$32+Inputs!$D$33/Inputs!$D$9)*Inputs!$D$10+Inputs!$D$35+Inputs!$D$36/Inputs!$D$9)/Model!$B$18 -> 0.22923611 | F7: =1-((Inputs!$D$14*(1-Inputs!$D$27)+Inputs!$D$15*(1-Inputs!$E$28)+Inputs!$D$16*(1+Inputs!$D$29)+Inputs!$D$30*Inputs!$D$18+Inputs!$D$31*Inputs!$D$32+Inputs!$D$33/Inputs!$D$9)*Inputs!$D$10+Inputs!$D$35+Inputs!$D$36/Inputs!$D$9)/Model!$B$18 -> 0.38017361 | G7: =(F7-E7)*100 -> 15.09375
A8: Change in Lane 3 hours | B8: =Inputs!C29 -> 0.1 | C8: =Inputs!D29 -> 0 | D8: =Inputs!E29 -> -0.1 | E8: =1-((Inputs!$D$14*(1-Inputs!$D$27)+Inputs!$D$15*(1-Inputs!$D$28)+Inputs!$D$16*(1+Inputs!$C$29)+Inputs!$D$30*Inputs!$D$18+Inputs!$D$31*Inputs!$D$32+Inputs!$D$33/Inputs!$D$9)*Inputs!$D$10+Inputs!$D$35+Inputs!$D$36/Inputs!$D$9)/Model!$B$18 -> 0.26298611 | F8: =1-((Inputs!$D$14*(1-Inputs!$D$27)+Inputs!$D$15*(1-Inputs!$D$28)+Inputs!$D$16*(1+Inputs!$E$29)+Inputs!$D$30*Inputs!$D$18+Inputs!$D$31*Inputs!$D$32+Inputs!$D$33/Inputs!$D$9)*Inputs!$D$10+Inputs!$D$35+Inputs!$D$36/Inputs!$D$9)/Model!$B$18 -> 0.28173611 | G8: =(F8-E8)*100 -> 1.875
A9: Share reworked in new design | B9: =Inputs!C30 -> 0.25 | C9: =Inputs!D30 -> 0.15 | D9: =Inputs!E30 -> 0.1 | E9: =1-((Inputs!$D$14*(1-Inputs!$D$27)+Inputs!$D$15*(1-Inputs!$D$28)+Inputs!$D$16*(1+Inputs!$D$29)+Inputs!$C$30*Inputs!$D$18+Inputs!$D$31*Inputs!$D$32+Inputs!$D$33/Inputs!$D$9)*Inputs!$D$10+Inputs!$D$35+Inputs!$D$36/Inputs!$D$9)/Model!$B$18 -> 0.21611111 | F9: =1-((Inputs!$D$14*(1-Inputs!$D$27)+Inputs!$D$15*(1-Inputs!$D$28)+Inputs!$D$16*(1+Inputs!$D$29)+Inputs!$E$30*Inputs!$D$18+Inputs!$D$31*Inputs!$D$32+Inputs!$D$33/Inputs!$D$9)*Inputs!$D$10+Inputs!$D$35+Inputs!$D$36/Inputs!$D$9)/Model!$B$18 -> 0.30048611 | G9: =(F9-E9)*100 -> 8.4375
A10: Share sampled at gates | B10: =Inputs!C31 -> 0.15 | C10: =Inputs!D31 -> 0.1 | D10: =Inputs!E31 -> 0.05 | E10: =1-((Inputs!$D$14*(1-Inputs!$D$27)+Inputs!$D$15*(1-Inputs!$D$28)+Inputs!$D$16*(1+Inputs!$D$29)+Inputs!$D$30*Inputs!$D$18+Inputs!$C$31*Inputs!$D$32+Inputs!$D$33/Inputs!$D$9)*Inputs!$D$10+Inputs!$D$35+Inputs!$D$36/Inputs!$D$9)/Model!$B$18 -> 0.26845486 | F10: =1-((Inputs!$D$14*(1-Inputs!$D$27)+Inputs!$D$15*(1-Inputs!$D$28)+Inputs!$D$16*(1+Inputs!$D$29)+Inputs!$D$30*Inputs!$D$18+Inputs!$E$31*Inputs!$D$32+Inputs!$D$33/Inputs!$D$9)*Inputs!$D$10+Inputs!$D$35+Inputs!$D$36/Inputs!$D$9)/Model!$B$18 -> 0.27626736 | G10: =(F10-E10)*100 -> 0.78125
A11: Hours per sampled asset | B11: =Inputs!C32 -> 0.3 | C11: =Inputs!D32 -> 0.25 | D11: =Inputs!E32 -> 0.2 | E11: =1-((Inputs!$D$14*(1-Inputs!$D$27)+Inputs!$D$15*(1-Inputs!$D$28)+Inputs!$D$16*(1+Inputs!$D$29)+Inputs!$D$30*Inputs!$D$18+Inputs!$D$31*Inputs!$C$32+Inputs!$D$33/Inputs!$D$9)*Inputs!$D$10+Inputs!$D$35+Inputs!$D$36/Inputs!$D$9)/Model!$B$18 -> 0.27079861 | F11: =1-((Inputs!$D$14*(1-Inputs!$D$27)+Inputs!$D$15*(1-Inputs!$D$28)+Inputs!$D$16*(1+Inputs!$D$29)+Inputs!$D$30*Inputs!$D$18+Inputs!$D$31*Inputs!$E$32+Inputs!$D$33/Inputs!$D$9)*Inputs!$D$10+Inputs!$D$35+Inputs!$D$36/Inputs!$D$9)/Model!$B$18 -> 0.27392361 | G11: =(F11-E11)*100 -> 0.3125
A12: Set-up hours per wave | B12: =Inputs!C33 -> 60 | C12: =Inputs!D33 -> 40 | D12: =Inputs!E33 -> 24 | E12: =1-((Inputs!$D$14*(1-Inputs!$D$27)+Inputs!$D$15*(1-Inputs!$D$28)+Inputs!$D$16*(1+Inputs!$D$29)+Inputs!$D$30*Inputs!$D$18+Inputs!$D$31*Inputs!$D$32+Inputs!$C$33/Inputs!$D$9)*Inputs!$D$10+Inputs!$D$35+Inputs!$D$36/Inputs!$D$9)/Model!$B$18 -> 0.25934028 | F12: =1-((Inputs!$D$14*(1-Inputs!$D$27)+Inputs!$D$15*(1-Inputs!$D$28)+Inputs!$D$16*(1+Inputs!$D$29)+Inputs!$D$30*Inputs!$D$18+Inputs!$D$31*Inputs!$D$32+Inputs!$E$33/Inputs!$D$9)*Inputs!$D$10+Inputs!$D$35+Inputs!$D$36/Inputs!$D$9)/Model!$B$18 -> 0.28277778 | G12: =(F12-E12)*100 -> 2.34375
A13: AI tool cost per asset | B13: =Inputs!C35 -> 3 | C13: =Inputs!D35 -> 1 | D13: =Inputs!E35 -> 0.5 | E13: =1-((Inputs!$D$14*(1-Inputs!$D$27)+Inputs!$D$15*(1-Inputs!$D$28)+Inputs!$D$16*(1+Inputs!$D$29)+Inputs!$D$30*Inputs!$D$18+Inputs!$D$31*Inputs!$D$32+Inputs!$D$33/Inputs!$D$9)*Inputs!$D$10+Inputs!$C$35+Inputs!$D$36/Inputs!$D$9)/Model!$B$18 -> 0.26194444 | F13: =1-((Inputs!$D$14*(1-Inputs!$D$27)+Inputs!$D$15*(1-Inputs!$D$28)+Inputs!$D$16*(1+Inputs!$D$29)+Inputs!$D$30*Inputs!$D$18+Inputs!$D$31*Inputs!$D$32+Inputs!$D$33/Inputs!$D$9)*Inputs!$D$10+Inputs!$E$35+Inputs!$D$36/Inputs!$D$9)/Model!$B$18 -> 0.27496528 | G13: =(F13-E13)*100 -> 1.3020833
A14: Platform cost per wave | B14: =Inputs!C36 -> 3000 | C14: =Inputs!D36 -> 2000 | D14: =Inputs!E36 -> 1000 | E14: =1-((Inputs!$D$14*(1-Inputs!$D$27)+Inputs!$D$15*(1-Inputs!$D$28)+Inputs!$D$16*(1+Inputs!$D$29)+Inputs!$D$30*Inputs!$D$18+Inputs!$D$31*Inputs!$D$32+Inputs!$D$33/Inputs!$D$9)*Inputs!$D$10+Inputs!$D$35+Inputs!$C$36/Inputs!$D$9)/Model!$B$18 -> 0.26151042 | F14: =1-((Inputs!$D$14*(1-Inputs!$D$27)+Inputs!$D$15*(1-Inputs!$D$28)+Inputs!$D$16*(1+Inputs!$D$29)+Inputs!$D$30*Inputs!$D$18+Inputs!$D$31*Inputs!$D$32+Inputs!$D$33/Inputs!$D$9)*Inputs!$D$10+Inputs!$D$35+Inputs!$E$36/Inputs!$D$9)/Model!$B$18 -> 0.28321181 | G14: =(F14-E14)*100 -> 2.1701389
A15: Central saving (all inputs central) | E15: =1-((Inputs!$D$14*(1-Inputs!$D$27)+Inputs!$D$15*(1-Inputs!$D$28)+Inputs!$D$16*(1+Inputs!$D$29)+Inputs!$D$30*Inputs!$D$18+Inputs!$D$31*Inputs!$D$32+Inputs!$D$33/Inputs!$D$9)*Inputs!$D$10+Inputs!$D$35+Inputs!$D$36/Inputs!$D$9)/Model!$B$18 -> 0.27236111
A17: B. The low-review-share test: what if review is a smaller share of today's 28 days than assumed? (central cut rates held constant)
A18: Review share of today's days | B18: Review days today | C18: Other days today | D18: Days saved in review | E18: Days saved elsewhere | F18: Total days saved | G18: Total saving as % of today's days | H18: Share of days saved from review | I18: Cut in review days (central) | J18: =1-Model!D32/Model!B32 -> 0.46666667
A19: =Inputs!D22/Inputs!D23 -> 0.53571429 | B19: =A19*Inputs!$D$23 -> 15 | C19: =Inputs!$D$23-B19 -> 13 | D19: =B19*$J$18 -> 7 | E19: =C19*$J$19 -> 3 | F19: =D19+E19 -> 10 | G19: =F19/Inputs!$D$23 -> 0.35714286 | H19: =D19/F19 -> 0.7 | I19: Cut in other days (central) | J19: =1-Model!D31/Model!B31 -> 0.23076923
A20: 0.45 | B20: =A20*Inputs!$D$23 -> 12.6 | C20: =Inputs!$D$23-B20 -> 15.4 | D20: =B20*$J$18 -> 5.88 | E20: =C20*$J$19 -> 3.5538462 | F20: =D20+E20 -> 9.4338462 | G20: =F20/Inputs!$D$23 -> 0.33692308 | H20: =D20/F20 -> 0.62328767
A21: 0.35 | B21: =A21*Inputs!$D$23 -> 9.8 | C21: =Inputs!$D$23-B21 -> 18.2 | D21: =B21*$J$18 -> 4.5733333 | E21: =C21*$J$19 -> 4.2 | F21: =D21+E21 -> 8.7733333 | G21: =F21/Inputs!$D$23 -> 0.31333333 | H21: =D21/F21 -> 0.5212766
A22: 0.27 | B22: =A22*Inputs!$D$23 -> 7.56 | C22: =Inputs!$D$23-B22 -> 20.44 | D22: =B22*$J$18 -> 3.528 | E22: =C22*$J$19 -> 4.7169231 | F22: =D22+E22 -> 8.2449231 | G22: =F22/Inputs!$D$23 -> 0.29446154 | H22: =D22/F22 -> 0.42789969
A25: C. Payback by volume: net cost saved per year and payback on the one-off cost
A26: Waves of this size per year | B26: Cautious: saved per year (£) | C26: Central: saved per year (£) | D26: Optimistic: saved per year (£) | E26: Cautious: payback (months) | F26: Central: payback (months) | G26: Optimistic: payback (months)
A27: 10 | B27: =Model!C$24*$A27 -> 73680 | C27: =Model!D$24*$A27 -> 251008 | D27: =Model!E$24*$A27 -> 464240 | E27: =IF(B27<=0,"n/a",Model!C$28/(B27/12)) -> 325.7329 | F27: =IF(C27<=0,"n/a",Model!D$28/(C27/12)) -> 57.368689 | G27: =IF(D27<=0,"n/a",Model!E$28/(D27/12)) -> 23.263829
A28: 20 | B28: =Model!C$24*$A28 -> 147360 | C28: =Model!D$24*$A28 -> 502016 | D28: =Model!E$24*$A28 -> 928480 | E28: =IF(B28<=0,"n/a",Model!C$28/(B28/12)) -> 162.86645 | F28: =IF(C28<=0,"n/a",Model!D$28/(C28/12)) -> 28.684345 | G28: =IF(D28<=0,"n/a",Model!E$28/(D28/12)) -> 11.631915
A29: 40 | B29: =Model!C$24*$A29 -> 294720 | C29: =Model!D$24*$A29 -> 1004032 | D29: =Model!E$24*$A29 -> 1856960 | E29: =IF(B29<=0,"n/a",Model!C$28/(B29/12)) -> 81.433225 | F29: =IF(C29<=0,"n/a",Model!D$28/(C29/12)) -> 14.342172 | G29: =IF(D29<=0,"n/a",Model!E$28/(D29/12)) -> 5.8159573
A30: 60 | B30: =Model!C$24*$A30 -> 442080 | C30: =Model!D$24*$A30 -> 1506048 | D30: =Model!E$24*$A30 -> 2785440 | E30: =IF(B30<=0,"n/a",Model!C$28/(B30/12)) -> 54.288817 | F30: =IF(C30<=0,"n/a",Model!D$28/(C30/12)) -> 9.5614482 | G30: =IF(D30<=0,"n/a",Model!E$28/(D30/12)) -> 3.8773048
A31: 100 | B31: =Model!C$24*$A31 -> 736800 | C31: =Model!D$24*$A31 -> 2510080 | D31: =Model!E$24*$A31 -> 4642400 | E31: =IF(B31<=0,"n/a",Model!C$28/(B31/12)) -> 32.57329 | F31: =IF(C31<=0,"n/a",Model!D$28/(C31/12)) -> 5.7368689 | G31: =IF(D31<=0,"n/a",Model!E$28/(D31/12)) -> 2.3263829

Sheet Checks
A1: Checks
A2: Each test should read OK. Tests 1 to 5 compare against the default inputs and will read CHECK if you change those inputs; that is expected.
A4: Test | B4: Result
A5: 1. Assets per wave equal 480 | B5: =IF(Inputs!D9=480,"OK","CHECK") -> OK
A6: 2. Hands-on hours per asset today equal 3.2 | B6: =IF(ROUND(Model!B12,2)=3.2,"OK","CHECK") -> OK
A7: 3. Hands-on cost of one wave today equals £92,160 | B7: =IF(ROUND(Model!B15*Inputs!D9,0)=92160,"OK","CHECK") -> OK
A8: 4. Total days today equal 28 | B8: =IF(Model!B33=28,"OK","CHECK") -> OK
A9: 5. Central days equal 18 (Deliverable 7) | B9: =IF(Model!D33=18,"OK","CHECK") -> OK
A10: 6. Hours saved by source add up to total hours saved (all scenarios) | B10: =IF(AND(ABS(Model!C42-Model!C22)<0.000001,ABS(Model!D42-Model!D22)<0.000001,ABS(Model!E42-Model!E22)<0.000001,ABS(Model!F42-Model!F22)<0.000001),"OK","CHECK") -> OK
A11: 7. Days saved by source add up to total days saved | B11: =IF(AND(ABS(Model!C48-(Model!B33-Model!C33))<0.000001,ABS(Model!D48-(Model!B33-Model!D33))<0.000001,ABS(Model!E48-(Model!B33-Model!E33))<0.000001),"OK","CHECK") -> OK
A12: 8. Cost saving rises from cautious to central to optimistic | B12: =IF(AND(Model!C19>Model!D19,Model!D19>Model!E19),"OK","CHECK") -> OK
A13: 9. Days saved rise from cautious to central to optimistic | B13: =IF(AND(Model!C33>Model!D33,Model!D33>Model!E33),"OK","CHECK") -> OK
A14: 10. Option A saves less cost and fewer days than option B (central) | B14: =IF(AND(Model!F19>Model!D19,Model!F33>Model!D33),"OK","CHECK") -> OK
A15: 11. Low-review-share test at the base share reproduces central days saved | B15: =IF(ABS(Sensitivity!F19-(Model!B33-Model!D33))<0.000001,"OK","CHECK") -> OK
A16: 12. Sensitivity central saving equals Model central saving | B16: =IF(ABS(Sensitivity!E15-(-Model!D19))<0.000001,"OK","CHECK") -> OK
A18: Overall | B18: =IF(COUNTIF(B5:B16,"OK")=12,"ALL OK","CHECK") -> ALL OK
A20: Information: central cost saving is inside the starting range of 20% to 30% from the project outline | B20: =IF(AND(-Model!D19>=0.2,-Model!D19<=0.3),"Inside","Outside") -> Inside
A21: Information: central days saved are inside the starting range of 30% to 45% | B21: =IF(AND(-Model!D34>=0.3,-Model!D34<=0.45),"Inside","Outside") -> Inside

Sheet Sources
A1: Sources used for cited facts (numbers match the Source Log, Deliverable 1)
A3: Ref | B3: Fact used | C3: Source | D3: Note
A4: 6 | B4: Unattributed claim of up to 70% faster content production and double asset utilisation | C4: Campaign Asia, WPP bets on $400 million Google AI alliance | D4: Headline only; used as a reference, never as a scenario input.
A5: 9 | B5: 46% say content gets stuck in review, 41% say it stalls in approvals, 70% say slowdowns affect revenue work; 96% say human oversight is critical | C5: PhotoShelter survey reported by CMOtech UK, 18 Mar 2026 | D5: Vendor survey of 388 US professionals; gives no days.
A6: 10 | B6: WPP Open used monthly by 70,000 staff; £500m annualised savings plan; AI investment | C6: WPP 2025 preliminary results (RNS), 26 Feb 2026 | D6: WPP's own publication.
A7: 11 | B7: WPP Production formed Jan to Feb 2026; "does not anticipate layoffs"; production logistics the main constraint | C7: eMarketer, 30 Jan 2026 | D7: No cost or time savings quoted.
A8: 12 | B8: WPP Production: faster turnaround and greater cost efficiency, no quantified targets | C8: Mediaweek, 23 Jan 2026 | D8: No quantified targets.
A9: D4/D5/D7 | B9: Hours per asset, lane split, 28 days, 15 review days, 18-day design target | C9: This project, Deliverables 4, 5 and 7 | D9: Illustrative case, not WPP data.
